line = 95 , type = <class 'lightgbm.basic.LightGBMError'> , message = Cannot open data file /opt/ml/input/data/validation/validation.bin
Traceback (most recent call last):
  File "/opt/program/train", line 83, in train
    model = lgb.train(
  File "/usr/local/lib/python3.8/site-packages/lightgbm/engine.py", line 232, in train
    booster.add_valid(valid_set, name_valid_set)
  File "/usr/local/lib/python3.8/site-packages/lightgbm/basic.py", line 1895, in add_valid
    data.construct().handle))
  File "/usr/local/lib/python3.8/site-packages/lightgbm/basic.py", line 1050, in construct
    self._lazy_init(self.data, label=self.label, reference=self.reference,
  File "/usr/local/lib/python3.8/site-packages/lightgbm/basic.py", line 877, in _lazy_init
    _safe_call(_LIB.LGBM_DatasetCreateFromFile(
  File "/usr/local/lib/python3.8/site-packages/lightgbm/basic.py", line 45, in _safe_call
    raise LightGBMError(decode_string(_LIB.LGBM_GetLastError()))
lightgbm.basic.LightGBMError: Cannot open data file /opt/ml/input/data/validation/validation.bin
